<sdf version='1.10'>
  <model name='mid360_robot'>
    <link name='base_footprint'>
      <inertial>
        <pose>0.02 0 0.068571428571428575 0 0 0</pose>
        <mass>1.3999999999999999</mass>
        <inertia>
          <ixx>0.013150476185526091</ixx>
          <ixy>4.9504130775628494e-12</ixy>
          <ixz>-0.001907623959787601</ixz>
          <iyy>0.01471047619047619</iyy>
          <iyz>-2.8581221460809119e-12</iyz>
          <izz>0.011800000004950101</izz>
        </inertia>
      </inertial>
      <collision name='base_footprint_fixed_joint_lump__base_link_collision'>
        <pose>0 0 0.040000000000000001 0 0 0</pose>
        <geometry>
          <box>
            <size>0.23999999999999999 0.10000000000000001 0.080000000000000002</size>
          </box>
        </geometry>
      </collision>
      <collision name='base_footprint_fixed_joint_lump__livox_frame_collision_1'>
        <pose>0.070000000000000007 0 0.14000000000000001 0 0.52359877560000001 0</pose>
        <geometry>
          <box>
            <size>0.087999999999999995 0.087999999999999995 0.040000000000000001</size>
          </box>
        </geometry>
        <surface>
          <contact>
            <ode/>
          </contact>
          <friction>
            <ode/>
          </friction>
        </surface>
      </collision>
      <visual name='base_footprint_fixed_joint_lump__base_link_visual'>
        <pose>0 0 0.040000000000000001 0 0 0</pose>
        <geometry>
          <box>
            <size>0.23999999999999999 0.10000000000000001 0.080000000000000002</size>
          </box>
        </geometry>
        <material>
          <diffuse>1 1 1 0.5</diffuse>
          <ambient>1 1 1 0.5</ambient>
        </material>
      </visual>
      <visual name='base_footprint_fixed_joint_lump__livox_frame_visual_1'>
        <pose>0.070000000000000007 0 0.14000000000000001 0 0.52359877560000001 0</pose>
        <geometry>
          <box>
            <size>0.087999999999999995 0.087999999999999995 0.040000000000000001</size>
          </box>
        </geometry>
        <material>
          <diffuse>0.125 0.125 0.125 1</diffuse>
          <ambient>0.125 0.125 0.125 1</ambient>
        </material>
      </visual>
      <sensor name='livox_frame_lidar' type='gpu_ray'>
        <visualize>false</visualize>
        <update_rate>10</update_rate>
        <plugin name='livox_frame_plugin' filename='liblivox_garden_gpu_laser.so'>
          <visualize>false</visualize>
          <frameName>livox_frame</frameName>
          <samples>20000</samples>
          <downsample>1</downsample>
          <csv_file_name>package://livox_gazebo_garden/scan_mode/mid360.csv</csv_file_name>
          <topic>/livox/lidar</topic>
        </plugin>
        <ray>
          <scan>
            <horizontal>
              <samples>360</samples>
              <resolution>1</resolution>
              <min_angle>0</min_angle>
              <max_angle>6.2831852000000001</max_angle>
            </horizontal>
            <vertical>
              <samples>60</samples>
              <resolution>1</resolution>
              <min_angle>-0.12601276984444446</min_angle>
              <max_angle>0.96377079651111108</max_angle>
            </vertical>
          </scan>
          <range>
            <min>0.10000000000000001</min>
            <max>100</max>
            <resolution>0.0050000000000000001</resolution>
          </range>
          <noise>
            <type>gaussian</type>
            <mean>0</mean>
            <stddev>0.002</stddev>
          </noise>
        </ray>
        <pose>0.070000000000000007 0 0.14000000000000001 0 0.52359900000000004 0</pose>
        <use_strict_rate>true</use_strict_rate>
      </sensor>
      <sensor name='livox_frame_imu' type='imu'>
        <always_on>true</always_on>
        <update_rate>200</update_rate>
        <visualize>false</visualize>
        <topic>/livox/imu</topic>
        <imu>
          <angular_velocity>
            <x>
              <noise type='gaussian'>
                <mean>0</mean>
                <stddev>0.00020000000000000001</stddev>
              </noise>
            </x>
            <y>
              <noise type='gaussian'>
                <mean>0</mean>
                <stddev>0.00020000000000000001</stddev>
              </noise>
            </y>
            <z>
              <noise type='gaussian'>
                <mean>0</mean>
                <stddev>0.00020000000000000001</stddev>
              </noise>
            </z>
          </angular_velocity>
          <linear_acceleration>
            <x>
              <noise type='gaussian'>
                <mean>0</mean>
                <stddev>0.017000000000000001</stddev>
              </noise>
            </x>
            <y>
              <noise type='gaussian'>
                <mean>0</mean>
                <stddev>0.017000000000000001</stddev>
              </noise>
            </y>
            <z>
              <noise type='gaussian'>
                <mean>0</mean>
                <stddev>0.017000000000000001</stddev>
              </noise>
            </z>
          </linear_acceleration>
        </imu>
        <plugin name='gz::sim::systems::Imu' filename='gz-sim-imu-system'/>
        <pose>0.070000000000000007 0 0.14000000000000001 0 0.52359900000000004 0</pose>
      </sensor>
    </link>
    <joint name='ahead_left_wheel_joint' type='revolute'>
      <pose relative_to='base_footprint'>0.080000000000000002 0.070000000000000007 0 0 0 0</pose>
      <parent>base_footprint</parent>
      <child>ahead_left_wheel</child>
      <axis>
        <xyz>0 1 0</xyz>
        <limit>
          <lower>-inf</lower>
          <upper>inf</upper>
        </limit>
        <dynamics>
          <spring_reference>0</spring_reference>
          <spring_stiffness>0</spring_stiffness>
        </dynamics>
      </axis>
    </joint>
    <link name='ahead_left_wheel'>
      <pose relative_to='ahead_left_wheel_joint'>0 0 0 0 0 0</pose>
      <inertial>
        <pose>0 0 0 0 0 0</pose>
        <mass>1</mass>
        <inertia>
          <ixx>0.01</ixx>
          <ixy>0</ixy>
          <ixz>0</ixz>
          <iyy>0.01</iyy>
          <iyz>0</iyz>
          <izz>0.01</izz>
        </inertia>
      </inertial>
      <collision name='ahead_left_wheel_collision'>
        <pose>0 0 0 1.5707899999999999 0 0</pose>
        <geometry>
          <cylinder>
            <length>0.032000000000000001</length>
            <radius>0.040000000000000001</radius>
          </cylinder>
        </geometry>
      </collision>
      <visual name='ahead_left_wheel_visual'>
        <pose>0 0 0 1.5707899999999999 0 0</pose>
        <geometry>
          <cylinder>
            <length>0.032000000000000001</length>
            <radius>0.040000000000000001</radius>
          </cylinder>
        </geometry>
        <material>
          <diffuse>0 0 0 1</diffuse>
          <ambient>0 0 0 1</ambient>
        </material>
      </visual>
    </link>
    <joint name='ahead_right_wheel_joint' type='revolute'>
      <pose relative_to='base_footprint'>0.080000000000000002 -0.070000000000000007 0 0 0 0</pose>
      <parent>base_footprint</parent>
      <child>ahead_right_wheel</child>
      <axis>
        <xyz>0 1 0</xyz>
        <limit>
          <lower>-inf</lower>
          <upper>inf</upper>
        </limit>
        <dynamics>
          <spring_reference>0</spring_reference>
          <spring_stiffness>0</spring_stiffness>
        </dynamics>
      </axis>
    </joint>
    <link name='ahead_right_wheel'>
      <pose relative_to='ahead_right_wheel_joint'>0 0 0 0 0 0</pose>
      <inertial>
        <pose>0 0 0 0 0 0</pose>
        <mass>1</mass>
        <inertia>
          <ixx>0.01</ixx>
          <ixy>0</ixy>
          <ixz>0</ixz>
          <iyy>0.01</iyy>
          <iyz>0</iyz>
          <izz>0.01</izz>
        </inertia>
      </inertial>
      <collision name='ahead_right_wheel_collision'>
        <pose>0 0 0 1.5707899999999999 0 0</pose>
        <geometry>
          <cylinder>
            <length>0.032000000000000001</length>
            <radius>0.040000000000000001</radius>
          </cylinder>
        </geometry>
      </collision>
      <visual name='ahead_right_wheel_visual'>
        <pose>0 0 0 1.5707899999999999 0 0</pose>
        <geometry>
          <cylinder>
            <length>0.032000000000000001</length>
            <radius>0.040000000000000001</radius>
          </cylinder>
        </geometry>
        <material>
          <diffuse>0 0 0 1</diffuse>
          <ambient>0 0 0 1</ambient>
        </material>
      </visual>
    </link>
    <joint name='behind_left_wheel_joint' type='revolute'>
      <pose relative_to='base_footprint'>-0.080000000000000002 0.070000000000000007 0 0 0 0</pose>
      <parent>base_footprint</parent>
      <child>behind_left_wheel</child>
      <axis>
        <xyz>0 1 0</xyz>
        <limit>
          <lower>-inf</lower>
          <upper>inf</upper>
        </limit>
        <dynamics>
          <spring_reference>0</spring_reference>
          <spring_stiffness>0</spring_stiffness>
        </dynamics>
      </axis>
    </joint>
    <link name='behind_left_wheel'>
      <pose relative_to='behind_left_wheel_joint'>0 0 0 0 0 0</pose>
      <inertial>
        <pose>0 0 0 0 0 0</pose>
        <mass>1</mass>
        <inertia>
          <ixx>0.01</ixx>
          <ixy>0</ixy>
          <ixz>0</ixz>
          <iyy>0.01</iyy>
          <iyz>0</iyz>
          <izz>0.01</izz>
        </inertia>
      </inertial>
      <collision name='behind_left_wheel_collision'>
        <pose>0 0 0 1.5707899999999999 0 0</pose>
        <geometry>
          <cylinder>
            <length>0.032000000000000001</length>
            <radius>0.040000000000000001</radius>
          </cylinder>
        </geometry>
      </collision>
      <visual name='behind_left_wheel_visual'>
        <pose>0 0 0 1.5707899999999999 0 0</pose>
        <geometry>
          <cylinder>
            <length>0.032000000000000001</length>
            <radius>0.040000000000000001</radius>
          </cylinder>
        </geometry>
        <material>
          <diffuse>0 0 0 1</diffuse>
          <ambient>0 0 0 1</ambient>
        </material>
      </visual>
    </link>
    <joint name='behind_right_wheel_joint' type='revolute'>
      <pose relative_to='base_footprint'>-0.080000000000000002 -0.070000000000000007 0 0 0 0</pose>
      <parent>base_footprint</parent>
      <child>behind_right_wheel</child>
      <axis>
        <xyz>0 1 0</xyz>
        <limit>
          <lower>-inf</lower>
          <upper>inf</upper>
        </limit>
        <dynamics>
          <spring_reference>0</spring_reference>
          <spring_stiffness>0</spring_stiffness>
        </dynamics>
      </axis>
    </joint>
    <link name='behind_right_wheel'>
      <pose relative_to='behind_right_wheel_joint'>0 0 0 0 0 0</pose>
      <inertial>
        <pose>0 0 0 0 0 0</pose>
        <mass>1</mass>
        <inertia>
          <ixx>0.01</ixx>
          <ixy>0</ixy>
          <ixz>0</ixz>
          <iyy>0.01</iyy>
          <iyz>0</iyz>
          <izz>0.01</izz>
        </inertia>
      </inertial>
      <collision name='behind_right_wheel_collision'>
        <pose>0 0 0 1.5707899999999999 0 0</pose>
        <geometry>
          <cylinder>
            <length>0.032000000000000001</length>
            <radius>0.040000000000000001</radius>
          </cylinder>
        </geometry>
      </collision>
      <visual name='behind_right_wheel_visual'>
        <pose>0 0 0 1.5707899999999999 0 0</pose>
        <geometry>
          <cylinder>
            <length>0.032000000000000001</length>
            <radius>0.040000000000000001</radius>
          </cylinder>
        </geometry>
        <material>
          <diffuse>0 0 0 1</diffuse>
          <ambient>0 0 0 1</ambient>
        </material>
      </visual>
    </link>
    <plugin name='gz::sim::systems::DiffDrive' filename='gz-sim-diff-drive-system'>
      <left_joint>behind_left_wheel_joint</left_joint>
      <right_joint>behind_right_wheel_joint</right_joint>
      <wheel_separation>0.14</wheel_separation>
      <wheel_radius>0.04</wheel_radius>
      <topic>/cmd_vel</topic>
    </plugin>
    <frame name='livox_frame_joint' attached_to='base_link'>
      <pose>0.070000000000000007 0 0.10000000000000001 0 0.52359877560000001 0</pose>
    </frame>
    <frame name='livox_frame' attached_to='livox_frame_joint'>
      <pose>0 0 0 0 0 0</pose>
    </frame>
    <frame name='base_link_joint' attached_to='base_footprint'>
      <pose>0 0 0.040000000000000001 0 0 0</pose>
    </frame>
    <frame name='base_link' attached_to='base_link_joint'>
      <pose>0 0 0 0 0 0</pose>
    </frame>
  </model>
</sdf>
